Workbook

Sheet Read me
A2: Hyperscaler off-balance-sheet commitments
A4: What this is | B4: Twelve quarters of two footnote disclosures for six hyperscalers: signed leases that have not yet commenced, and non-cancelable purchase commitments. Both sit outside the balance sheet but bind future cash.
A5: Units | B5: All figures in USD millions on the Data sheet; matrix sheets display $bn.
A6: Quarters | B6: 2023Q3 to 2026Q2 (calendar-aligned).
A8: Why leases sit off balance sheet | B8: Signed leases that have not yet commenced. Under ASC 842 a lease is not recognised until the lessor makes the asset available, so these sit in the footnotes only.
A9: Purchase commitments | B9: Non-cancelable purchase / supply / unconditional purchase obligations disclosed in the commitments footnote.
A11: Definitions are NOT uniform | B11: The six filers do not use one definition. Alphabet reports 'purchase commitments and other contractual obligations'; Microsoft a contractual-obligations 'purchase commitments' line; Meta 'non-cancelable contractual commitments'; Amazon 'unconditional purchase obligations'; NVIDIA 'purchase commitments and supply obligations'; Oracle 'unconditional purchase and certain other obligations'. Totals across companies are therefore indicative, not like-for-like.
A13: How the figures were collected | B13: SEC.gov and every filing mirror were unreachable from the build environment (egress policy blocked all hosts except GitHub). Figures were collected by searching filing text. Each observation carries its provenance; gaps are left empty rather than estimated.
A15: Provenance codes
A16: filing | B16: Figure quoted directly from the filing's footnote text or commitments table.
A17: filing_table | B17: Figure from the filing's maturity table; the year-by-year rows sum to the stated total (arithmetic check passed).
A18: press | B18: Figure reported by financial press citing the filing; not independently re-read.
A19: derived | B19: Approximate, inferred from a reported change or ratio. Treat as indicative.
A21: Series with no data
A22: NVDA_uncommenced_leases | B22: NVIDIA does not disclose a material 'leases not yet commenced' balance. Its off-balance-sheet exposure sits in supply and capacity purchase obligations instead, so this series is empty by disclosure, not by omission.
A23: ORCL_early | B23: Oracle only began disclosing a large uncommenced-lease balance in fiscal 2026; earlier quarters carried immaterial amounts.
A25: Empty cell = the company did not disclose a figure we could source for that quarter. It is not a zero, and it is not an estimate.

Sheet Data
A1: Ticker | B1: Company | C1: CIK | D1: Calendar quarter | E1: Period end | F1: Metric | G1: Metric label | H1: Value ($m) | I1: Value ($bn) | J1: Provenance | K1: Note
A2: GOOGL | B2: Alphabet Inc. | C2: 0001652044 | D2: 2024Q2 | E2: 2024-06-30 | F2: purchase_commitments | G2: Purchase commitments | H2: 54900 | I2: =H2/1000 | J2: filing | K2: $41.0bn short-term.
A3: GOOGL | B3: Alphabet Inc. | C3: 0001652044 | D3: 2025Q1 | E3: 2025-03-31 | F3: purchase_commitments | G3: Purchase commitments | H3: 62100 | I3: =H3/1000 | J3: filing | K3: $41.5bn short-term.
A4: GOOGL | B4: Alphabet Inc. | C4: 0001652044 | D4: 2025Q2 | E4: 2025-06-30 | F4: purchase_commitments | G4: Purchase commitments | H4: 72500 | I4: =H4/1000 | J4: filing | K4: $51.0bn short-term.
A5: GOOGL | B5: Alphabet Inc. | C5: 0001652044 | D5: 2025Q4 | E5: 2025-12-31 | F5: purchase_commitments | G5: Purchase commitments | H5: 149100 | I5: =H5/1000 | J5: filing | K5: $113.0bn short-term.
A6: GOOGL | B6: Alphabet Inc. | C6: 0001652044 | D6: 2026Q1 | E6: 2026-03-31 | F6: purchase_commitments | G6: Purchase commitments | H6: 332400 | I6: =H6/1000 | J6: filing | K6: $138.0bn short-term. Matches the Morgan Stanley 1Q26 chart ($332bn).
A7: GOOGL | B7: Alphabet Inc. | C7: 0001652044 | D7: 2026Q2 | E7: 2026-06-30 | F7: purchase_commitments | G7: Purchase commitments | H7: 707000 | I7: =H7/1000 | J7: filing | K7: Footnote figure. A broader MD&A measure including open purchase orders was reported at ~$811bn.
A8: MSFT | B8: Microsoft Corporation | C8: 0000789019 | D8: 2025Q2 | E8: 2025-06-30 | F8: purchase_commitments | G8: Purchase commitments | H8: 109950 | I8: =H8/1000 | J8: filing | K8: FY2025 10-K contractual obligations table. Construction commitments of $32.15bn are additional.
A9: MSFT | B9: Microsoft Corporation | C9: 0000789019 | D9: 2026Q1 | E9: 2026-03-31 | F9: purchase_commitments | G9: Purchase commitments | H9: 142000 | I9: =H9/1000 | J9: press | K9: Morgan Stanley 1Q26 chart; not re-read from the filing.
A10: MSFT | B10: Microsoft Corporation | C10: 0000789019 | D10: 2026Q2 | E10: 2026-06-30 | F10: purchase_commitments | G10: Purchase commitments | H10: 194060 | I10: =H10/1000 | J10: filing | K10: FY2026 10-K contractual obligations table. Construction commitments of $34.57bn are additional.
A11: META | B11: Meta Platforms, Inc. | C11: 0001326801 | D11: 2024Q3 | E11: 2024-09-30 | F11: purchase_commitments | G11: Purchase commitments | H11: 32140 | I11: =H11/1000 | J11: filing
A12: META | B12: Meta Platforms, Inc. | C12: 0001326801 | D12: 2025Q1 | E12: 2025-03-31 | F12: purchase_commitments | G12: Purchase commitments | H12: 30050 | I12: =H12/1000 | J12: filing | K12: Mostly servers, network infrastructure and content costs.
A13: META | B13: Meta Platforms, Inc. | C13: 0001326801 | D13: 2025Q2 | E13: 2025-06-30 | F13: purchase_commitments | G13: Purchase commitments | H13: 28000 | I13: =H13/1000 | J13: derived | K13: Approximate: press describes the run from ~$28bn to $349.3bn over the four quarters to 2026Q2.
A14: META | B14: Meta Platforms, Inc. | C14: 0001326801 | D14: 2025Q3 | E14: 2025-09-30 | F14: purchase_commitments | G14: Purchase commitments | H14: 81190 | I14: =H14/1000 | J14: filing | K14: Mostly third-party cloud capacity arrangements.
A15: META | B15: Meta Platforms, Inc. | C15: 0001326801 | D15: 2025Q4 | E15: 2025-12-31 | F15: purchase_commitments | G15: Purchase commitments | H15: 131050 | I15: =H15/1000 | J15: filing | K15: $30.63bn due in 2026.
A16: META | B16: Meta Platforms, Inc. | C16: 0001326801 | D16: 2026Q1 | E16: 2026-03-31 | F16: purchase_commitments | G16: Purchase commitments | H16: 237670 | I16: =H16/1000 | J16: filing | K16: Matches the Morgan Stanley 1Q26 chart ($238bn).
A17: META | B17: Meta Platforms, Inc. | C17: 0001326801 | D17: 2026Q2 | E17: 2026-06-30 | F17: purchase_commitments | G17: Purchase commitments | H17: 349310 | I17: =H17/1000 | J17: filing | K17: Multi-year cloud deals drove a ~$112bn step up in the quarter.
A18: AMZN | B18: Amazon.com, Inc. | C18: 0001018724 | D18: 2024Q4 | E18: 2024-12-31 | F18: purchase_commitments | G18: Purchase commitments | H18: 50375 | I18: =H18/1000 | J18: filing_table | K18: Unconditional purchase obligations.
A19: AMZN | B19: Amazon.com, Inc. | C19: 0001018724 | D19: 2025Q2 | E19: 2025-06-30 | F19: purchase_commitments | G19: Purchase commitments | H19: 71018 | I19: =H19/1000 | J19: filing_table | K19: Unconditional purchase obligations.
A20: AMZN | B20: Amazon.com, Inc. | C20: 0001018724 | D20: 2025Q4 | E20: 2025-12-31 | F20: purchase_commitments | G20: Purchase commitments | H20: 84772 | I20: =H20/1000 | J20: filing_table | K20: Maturity rows sum to the total.
A21: AMZN | B21: Amazon.com, Inc. | C21: 0001018724 | D21: 2026Q1 | E21: 2026-03-31 | F21: purchase_commitments | G21: Purchase commitments | H21: 103768 | I21: =H21/1000 | J21: filing_table | K21: Maturity rows sum to the total. Matches the Morgan Stanley 1Q26 chart ($104bn). A further $18.81bn of 'other commitments' is disclosed separately.
A22: NVDA | B22: NVIDIA Corporation | C22: 0001045810 | D22: 2025Q1 | E22: 2025-04-27 | F22: purchase_commitments | G22: Purchase commitments | H22: 43500 | I22: =H22/1000 | J22: filing | K22: $29.8bn inventory/supply + $13.7bn other purchase obligations (of which $10.6bn multi-year cloud).
A23: NVDA | B23: NVIDIA Corporation | C23: 0001045810 | D23: 2025Q4 | E23: 2026-01-25 | F23: purchase_commitments | G23: Purchase commitments | H23: 95200 | I23: =H23/1000 | J23: filing | K23: FY2026 10-K. Inventory purchase and long-term supply/capacity obligations; excludes other purchase obligations, so understates the comparable total.
... A33: GOOGL | B33: Alphabet Inc. | C33: 0001652044 | D33: 2026Q1 | E33: 2026-03-31 | F33: uncommenced_leases | G33: Uncommenced lease commitments | H33: 75600 | I33: =H33/1000 | J33: filing | K33: Commence 2026-2031, terms 1-25 years.
A34: GOOGL | B34: Alphabet Inc. | C34: 0001652044 | D34: 2026Q2 | E34: 2026-06-30 | F34: uncommenced_leases | G34: Uncommenced lease commitments | H34: 85200 | I34: =H34/1000 | J34: filing
A35: MSFT | B35: Microsoft Corporation | C35: 0000789019 | D35: 2023Q3 | E35: 2023-09-30 | F35: uncommenced_leases | G35: Uncommenced lease commitments | H35: 82600 | I35: =H35/1000 | J35: filing | K35: $7.5bn operating + $75.1bn finance.
A36: MSFT | B36: Microsoft Corporation | C36: 0000789019 | D36: 2024Q1 | E36: 2024-03-31 | F36: uncommenced_leases | G36: Uncommenced lease commitments | H36: 96200 | I36: =H36/1000 | J36: filing | K36: $8.4bn operating + $87.8bn finance.
A37: MSFT | B37: Microsoft Corporation | C37: 0000789019 | D37: 2024Q2 | E37: 2024-06-30 | F37: uncommenced_leases | G37: Uncommenced lease commitments | H37: 117000 | I37: =H37/1000 | J37: filing | K37: $8.6bn operating + $108.4bn finance. FY2024 10-K.
A38: MSFT | B38: Microsoft Corporation | C38: 0000789019 | D38: 2024Q3 | E38: 2024-09-30 | F38: uncommenced_leases | G38: Uncommenced lease commitments | H38: 116100 | I38: =H38/1000 | J38: filing | K38: $7.4bn operating + $108.7bn finance.
A39: MSFT | B39: Microsoft Corporation | C39: 0000789019 | D39: 2025Q1 | E39: 2025-03-31 | F39: uncommenced_leases | G39: Uncommenced lease commitments | H39: 99200 | I39: =H39/1000 | J39: filing | K39: $4.4bn operating + $94.8bn finance.
A40: MSFT | B40: Microsoft Corporation | C40: 0000789019 | D40: 2025Q2 | E40: 2025-06-30 | F40: uncommenced_leases | G40: Uncommenced lease commitments | H40: 92700 | I40: =H40/1000 | J40: filing | K40: FY2025 10-K. Terms running to fiscal 2031.
A41: MSFT | B41: Microsoft Corporation | C41: 0000789019 | D41: 2025Q3 | E41: 2025-09-30 | F41: uncommenced_leases | G41: Uncommenced lease commitments | H41: 106200 | I41: =H41/1000 | J41: filing | K41: Commence fiscal 2026-2031, terms 1-20 years.
A42: MSFT | B42: Microsoft Corporation | C42: 0000789019 | D42: 2025Q4 | E42: 2025-12-31 | F42: uncommenced_leases | G42: Uncommenced lease commitments | H42: 155100 | I42: =H42/1000 | J42: filing | K42: Commence fiscal 2026-2031.
A43: MSFT | B43: Microsoft Corporation | C43: 0000789019 | D43: 2026Q1 | E43: 2026-03-31 | F43: uncommenced_leases | G43: Uncommenced lease commitments | H43: 196600 | I43: =H43/1000 | J43: filing
A44: MSFT | B44: Microsoft Corporation | C44: 0000789019 | D44: 2026Q2 | E44: 2026-06-30 | F44: uncommenced_leases | G44: Uncommenced lease commitments | H44: 329100 | I44: =H44/1000 | J44: filing | K44: FY2026 10-K. Up $132.5bn in one quarter; commence fiscal 2027-2033.
A45: META | B45: Meta Platforms, Inc. | C45: 0001326801 | D45: 2024Q3 | E45: 2024-09-30 | F45: uncommenced_leases | G45: Uncommenced lease commitments | H45: 18490 | I45: =H45/1000 | J45: filing | K45: Mostly data centres and colocations.
A46: META | B46: Meta Platforms, Inc. | C46: 0001326801 | D46: 2025Q1 | E46: 2025-03-31 | F46: uncommenced_leases | G46: Uncommenced lease commitments | H46: 35270 | I46: =H46/1000 | J46: filing
A47: META | B47: Meta Platforms, Inc. | C47: 0001326801 | D47: 2025Q2 | E47: 2025-06-30 | F47: uncommenced_leases | G47: Uncommenced lease commitments | H47: 52560 | I47: =H47/1000 | J47: filing | K47: Commence remainder of 2025 through 2034.
A48: META | B48: Meta Platforms, Inc. | C48: 0001326801 | D48: 2025Q3 | E48: 2025-09-30 | F48: uncommenced_leases | G48: Uncommenced lease commitments | H48: 58140 | I48: =H48/1000 | J48: filing
A49: META | B49: Meta Platforms, Inc. | C49: 0001326801 | D49: 2025Q4 | E49: 2025-12-31 | F49: uncommenced_leases | G49: Uncommenced lease commitments | H49: 103770 | I49: =H49/1000 | J49: filing | K49: Commence 2026-2030, terms up to 30 years.
...

Sheet Uncommenced lease commitments
A1: Uncommenced lease commitments
A2: USD billions. Blank = not disclosed / not sourced; never treated as zero.
A4: Calendar quarter | B4: GOOGL | C4: MSFT | D4: META | E4: AMZN | F4: NVDA | G4: ORCL | H4: Total | I4: Reported
A5: 2023Q3 | B5: =IF(COUNTIFS(Data!$A$2:$A$60,"GOOGL",Data!$D$2:$D$60,$A5,Data!$F$2:$F$60,"uncommenced_leases")=0,"",SUMIFS(Data!$H$2:$H$60,Data!$A$2:$A$60,"GOOGL",Data!$D$2:$D$60,$A5,Data!$F$2:$F$60,"uncommenced_leases")/1000) | C5: =IF(COUNTIFS(Data!$A$2:$A$60,"MSFT",Data!$D$2:$D$60,$A5,Data!$F$2:$F$60,"uncommenced_leases")=0,"",SUMIFS(Data!$H$2:$H$60,Data!$A$2:$A$60,"MSFT",Data!$D$2:$D$60,$A5,Data!$F$2:$F$60,"uncommenced_leases")/1000) | D5: =IF(COUNTIFS(Data!$A$2:$A$60,"META",Data!$D$2:$D$60,$A5,Data!$F$2:$F$60,"uncommenced_leases")=0,"",SUMIFS(Data!$H$2:$H$60,Data!$A$2:$A$60,"META",Data!$D$2:$D$60,$A5,Data!$F$2:$F$60,"uncommenced_leases")/1000) | E5: =IF(COUNTIFS(Data!$A$2:$A$60,"AMZN",Data!$D$2:$D$60,$A5,Data!$F$2:$F$60,"uncommenced_leases")=0,"",SUMIFS(Data!$H$2:$H$60,Data!$A$2:$A$60,"AMZN",Data!$D$2:$D$60,$A5,Data!$F$2:$F$60,"uncommenced_leases")/1000) | F5: =IF(COUNTIFS(Data!$A$2:$A$60,"NVDA",Data!$D$2:$D$60,$A5,Data!$F$2:$F$60,"uncommenced_leases")=0,"",SUMIFS(Data!$H$2:$H$60,Data!$A$2:$A$60,"NVDA",Data!$D$2:$D$60,$A5,Data!$F$2:$F$60,"uncommenced_leases")/1000) | G5: =IF(COUNTIFS(Data!$A$2:$A$60,"ORCL",Data!$D$2:$D$60,$A5,Data!$F$2:$F$60,"uncommenced_leases")=0,"",SUMIFS(Data!$H$2:$H$60,Data!$A$2:$A$60,"ORCL",Data!$D$2:$D$60,$A5,Data!$F$2:$F$60,"uncommenced_leases")/1000) | H5: =IF(COUNT(B5:G5)=0,"",SUM(B5:G5)) | I5: =COUNT(B5:G5)&" of 6"
A6: 2023Q4 | B6: =IF(COUNTIFS(Data!$A$2:$A$60,"GOOGL",Data!$D$2:$D$60,$A6,Data!$F$2:$F$60,"uncommenced_leases")=0,"",SUMIFS(Data!$H$2:$H$60,Data!$A$2:$A$60,"GOOGL",Data!$D$2:$D$60,$A6,Data!$F$2:$F$60,"uncommenced_leases")/1000) | C6: =IF(COUNTIFS(Data!$A$2:$A$60,"MSFT",Data!$D$2:$D$60,$A6,Data!$F$2:$F$60,"uncommenced_leases")=0,"",SUMIFS(Data!$H$2:$H$60,Data!$A$2:$A$60,"MSFT",Data!$D$2:$D$60,$A6,Data!$F$2:$F$60,"uncommenced_leases")/1000) | D6: =IF(COUNTIFS(Data!$A$2:$A$60,"META",Data!$D$2:$D$60,$A6,Data!$F$2:$F$60,"uncommenced_leases")=0,"",SUMIFS(Data!$H$2:$H$60,Data!$A$2:$A$60,"META",Data!$D$2:$D$60,$A6,Data!$F$2:$F$60,"uncommenced_leases")/1000) | E6: =IF(COUNTIFS(Data!$A$2:$A$60,"AMZN",Data!$D$2:$D$60,$A6,Data!$F$2:$F$60,"uncommenced_leases")=0,"",SUMIFS(Data!$H$2:$H$60,Data!$A$2:$A$60,"AMZN",Data!$D$2:$D$60,$A6,Data!$F$2:$F$60,"uncommenced_leases")/1000) | F6: =IF(COUNTIFS(Data!$A$2:$A$60,"NVDA",Data!$D$2:$D$60,$A6,Data!$F$2:$F$60,"uncommenced_leases")=0,"",SUMIFS(Data!$H$2:$H$60,Data!$A$2:$A$60,"NVDA",Data!$D$2:$D$60,$A6,Data!$F$2:$F$60,"uncommenced_leases")/1000) | G6: =IF(COUNTIFS(Data!$A$2:$A$60,"ORCL",Data!$D$2:$D$60,$A6,Data!$F$2:$F$60,"uncommenced_leases")=0,"",SUMIFS(Data!$H$2:$H$60,Data!$A$2:$A$60,"ORCL",Data!$D$2:$D$60,$A6,Data!$F$2:$F$60,"uncommenced_leases")/1000) | H6: =IF(COUNT(B6:G6)=0,"",SUM(B6:G6)) | I6: =COUNT(B6:G6)&" of 6"
A7: 2024Q1 | B7: =IF(COUNTIFS(Data!$A$2:$A$60,"GOOGL",Data!$D$2:$D$60,$A7,Data!$F$2:$F$60,"uncommenced_leases")=0,"",SUMIFS(Data!$H$2:$H$60,Data!$A$2:$A$60,"GOOGL",Data!$D$2:$D$60,$A7,Data!$F$2:$F$60,"uncommenced_leases")/1000) | C7: =IF(COUNTIFS(Data!$A$2:$A$60,"MSFT",Data!$D$2:$D$60,$A7,Data!$F$2:$F$60,"uncommenced_leases")=0,"",SUMIFS(Data!$H$2:$H$60,Data!$A$2:$A$60,"MSFT",Data!$D$2:$D$60,$A7,Data!$F$2:$F$60,"uncommenced_leases")/1000) | D7: =IF(COUNTIFS(Data!$A$2:$A$60,"META",Data!$D$2:$D$60,$A7,Data!$F$2:$F$60,"uncommenced_leases")=0,"",SUMIFS(Data!$H$2:$H$60,Data!$A$2:$A$60,"META",Data!$D$2:$D$60,$A7,Data!$F$2:$F$60,"uncommenced_leases")/1000) | E7: =IF(COUNTIFS(Data!$A$2:$A$60,"AMZN",Data!$D$2:$D$60,$A7,Data!$F$2:$F$60,"uncommenced_leases")=0,"",SUMIFS(Data!$H$2:$H$60,Data!$A$2:$A$60,"AMZN",Data!$D$2:$D$60,$A7,Data!$F$2:$F$60,"uncommenced_leases")/1000) | F7: =IF(COUNTIFS(Data!$A$2:$A$60,"NVDA",Data!$D$2:$D$60,$A7,Data!$F$2:$F$60,"uncommenced_leases")=0,"",SUMIFS(Data!$H$2:$H$60,Data!$A$2:$A$60,"NVDA",Data!$D$2:$D$60,$A7,Data!$F$2:$F$60,"uncommenced_leases")/1000) | G7: =IF(COUNTIFS(Data!$A$2:$A$60,"ORCL",Data!$D$2:$D$60,$A7,Data!$F$2:$F$60,"uncommenced_leases")=0,"",SUMIFS(Data!$H$2:$H$60,Data!$A$2:$A$60,"ORCL",Data!$D$2:$D$60,$A7,Data!$F$2:$F$60,"uncommenced_leases")/1000) | H7: =IF(COUNT(B7:G7)=0,"",SUM(B7:G7)) | I7: =COUNT(B7:G7)&" of 6"
A8: 2024Q2 | B8: =IF(COUNTIFS(Data!$A$2:$A$60,"GOOGL",Data!$D$2:$D$60,$A8,Data!$F$2:$F$60,"uncommenced_leases")=0,"",SUMIFS(Data!$H$2:$H$60,Data!$A$2:$A$60,"GOOGL",Data!$D$2:$D$60,$A8,Data!$F$2:$F$60,"uncommenced_leases")/1000) | C8: =IF(COUNTIFS(Data!$A$2:$A$60,"MSFT",Data!$D$2:$D$60,$A8,Data!$F$2:$F$60,"uncommenced_leases")=0,"",SUMIFS(Data!$H$2:$H$60,Data!$A$2:$A$60,"MSFT",Data!$D$2:$D$60,$A8,Data!$F$2:$F$60,"uncommenced_leases")/1000) | D8: =IF(COUNTIFS(Data!$A$2:$A$60,"META",Data!$D$2:$D$60,$A8,Data!$F$2:$F$60,"uncommenced_leases")=0,"",SUMIFS(Data!$H$2:$H$60,Data!$A$2:$A$60,"META",Data!$D$2:$D$60,$A8,Data!$F$2:$F$60,"uncommenced_leases")/1000) | E8: =IF(COUNTIFS(Data!$A$2:$A$60,"AMZN",Data!$D$2:$D$60,$A8,Data!$F$2:$F$60,"uncommenced_leases")=0,"",SUMIFS(Data!$H$2:$H$60,Data!$A$2:$A$60,"AMZN",Data!$D$2:$D$60,$A8,Data!$F$2:$F$60,"uncommenced_leases")/1000) | F8: =IF(COUNTIFS(Data!$A$2:$A$60,"NVDA",Data!$D$2:$D$60,$A8,Data!$F$2:$F$60,"uncommenced_leases")=0,"",SUMIFS(Data!$H$2:$H$60,Data!$A$2:$A$60,"NVDA",Data!$D$2:$D$60,$A8,Data!$F$2:$F$60,"uncommenced_leases")/1000) | G8: =IF(COUNTIFS(Data!$A$2:$A$60,"ORCL",Data!$D$2:$D$60,$A8,Data!$F$2:$F$60,"uncommenced_leases")=0,"",SUMIFS(Data!$H$2:$H$60,Data!$A$2:$A$60,"ORCL",Data!$D$2:$D$60,$A8,Data!$F$2:$F$60,"uncommenced_leases")/1000) | H8: =IF(COUNT(B8:G8)=0,"",SUM(B8:G8)) | I8: =COUNT(B8:G8)&" of 6"
A9: 2024Q3 | B9: =IF(COUNTIFS(Data!$A$2:$A$60,"GOOGL",Data!$D$2:$D$60,$A9,Data!$F$2:$F$60,"uncommenced_leases")=0,"",SUMIFS(Data!$H$2:$H$60,Data!$A$2:$A$60,"GOOGL",Data!$D$2:$D$60,$A9,Data!$F$2:$F$60,"uncommenced_leases")/1000) | C9: =IF(COUNTIFS(Data!$A$2:$A$60,"MSFT",Data!$D$2:$D$60,$A9,Data!$F$2:$F$60,"uncommenced_leases")=0,"",SUMIFS(Data!$H$2:$H$60,Data!$A$2:$A$60,"MSFT",Data!$D$2:$D$60,$A9,Data!$F$2:$F$60,"uncommenced_leases")/1000) | D9: =IF(COUNTIFS(Data!$A$2:$A$60,"META",Data!$D$2:$D$60,$A9,Data!$F$2:$F$60,"uncommenced_leases")=0,"",SUMIFS(Data!$H$2:$H$60,Data!$A$2:$A$60,"META",Data!$D$2:$D$60,$A9,Data!$F$2:$F$60,"uncommenced_leases")/1000) | E9: =IF(COUNTIFS(Data!$A$2:$A$60,"AMZN",Data!$D$2:$D$60,$A9,Data!$F$2:$F$60,"uncommenced_leases")=0,"",SUMIFS(Data!$H$2:$H$60,Data!$A$2:$A$60,"AMZN",Data!$D$2:$D$60,$A9,Data!$F$2:$F$60,"uncommenced_leases")/1000) | F9: =IF(COUNTIFS(Data!$A$2:$A$60,"NVDA",Data!$D$2:$D$60,$A9,Data!$F$2:$F$60,"uncommenced_leases")=0,"",SUMIFS(Data!$H$2:$H$60,Data!$A$2:$A$60,"NVDA",Data!$D$2:$D$60,$A9,Data!$F$2:$F$60,"uncommenced_leases")/1000) | G9: =IF(COUNTIFS(Data!$A$2:$A$60,"ORCL",Data!$D$2:$D$60,$A9,Data!$F$2:$F$60,"uncommenced_leases")=0,"",SUMIFS(Data!$H$2:$H$60,Data!$A$2:$A$60,"ORCL",Data!$D$2:$D$60,$A9,Data!$F$2:$F$60,"uncommenced_leases")/1000) | H9: =IF(COUNT(B9:G9)=0,"",SUM(B9:G9)) | I9: =COUNT(B9:G9)&" of 6"
A10: 2024Q4 | B10: =IF(COUNTIFS(Data!$A$2:$A$60,"GOOGL",Data!$D$2:$D$60,$A10,Data!$F$2:$F$60,"uncommenced_leases")=0,"",SUMIFS(Data!$H$2:$H$60,Data!$A$2:$A$60,"GOOGL",Data!$D$2:$D$60,$A10,Data!$F$2:$F$60,"uncommenced_leases")/1000) | C10: =IF(COUNTIFS(Data!$A$2:$A$60,"MSFT",Data!$D$2:$D$60,$A10,Data!$F$2:$F$60,"uncommenced_leases")=0,"",SUMIFS(Data!$H$2:$H$60,Data!$A$2:$A$60,"MSFT",Data!$D$2:$D$60,$A10,Data!$F$2:$F$60,"uncommenced_leases")/1000) | D10: =IF(COUNTIFS(Data!$A$2:$A$60,"META",Data!$D$2:$D$60,$A10,Data!$F$2:$F$60,"uncommenced_leases")=0,"",SUMIFS(Data!$H$2:$H$60,Data!$A$2:$A$60,"META",Data!$D$2:$D$60,$A10,Data!$F$2:$F$60,"uncommenced_leases")/1000) | E10: =IF(COUNTIFS(Data!$A$2:$A$60,"AMZN",Data!$D$2:$D$60,$A10,Data!$F$2:$F$60,"uncommenced_leases")=0,"",SUMIFS(Data!$H$2:$H$60,Data!$A$2:$A$60,"AMZN",Data!$D$2:$D$60,$A10,Data!$F$2:$F$60,"uncommenced_leases")/1000) | F10: =IF(COUNTIFS(Data!$A$2:$A$60,"NVDA",Data!$D$2:$D$60,$A10,Data!$F$2:$F$60,"uncommenced_leases")=0,"",SUMIFS(Data!$H$2:$H$60,Data!$A$2:$A$60,"NVDA",Data!$D$2:$D$60,$A10,Data!$F$2:$F$60,"uncommenced_leases")/1000) | G10: =IF(COUNTIFS(Data!$A$2:$A$60,"ORCL",Data!$D$2:$D$60,$A10,Data!$F$2:$F$60,"uncommenced_leases")=0,"",SUMIFS(Data!$H$2:$H$60,Data!$A$2:$A$60,"ORCL",Data!$D$2:$D$60,$A10,Data!$F$2:$F$60,"uncommenced_leases")/1000) | H10: =IF(COUNT(B10:G10)=0,"",SUM(B10:G10)) | I10: =COUNT(B10:G10)&" of 6"
A11: 2025Q1 | B11: =IF(COUNTIFS(Data!$A$2:$A$60,"GOOGL",Data!$D$2:$D$60,$A11,Data!$F$2:$F$60,"uncommenced_leases")=0,"",SUMIFS(Data!$H$2:$H$60,Data!$A$2:$A$60,"GOOGL",Data!$D$2:$D$60,$A11,Data!$F$2:$F$60,"uncommenced_leases")/1000) | C11: =IF(COUNTIFS(Data!$A$2:$A$60,"MSFT",Data!$D$2:$D$60,$A11,Data!$F$2:$F$60,"uncommenced_leases")=0,"",SUMIFS(Data!$H$2:$H$60,Data!$A$2:$A$60,"MSFT",Data!$D$2:$D$60,$A11,Data!$F$2:$F$60,"uncommenced_leases")/1000) | D11: =IF(COUNTIFS(Data!$A$2:$A$60,"META",Data!$D$2:$D$60,$A11,Data!$F$2:$F$60,"uncommenced_leases")=0,"",SUMIFS(Data!$H$2:$H$60,Data!$A$2:$A$60,"META",Data!$D$2:$D$60,$A11,Data!$F$2:$F$60,"uncommenced_leases")/1000) | E11: =IF(COUNTIFS(Data!$A$2:$A$60,"AMZN",Data!$D$2:$D$60,$A11,Data!$F$2:$F$60,"uncommenced_leases")=0,"",SUMIFS(Data!$H$2:$H$60,Data!$A$2:$A$60,"AMZN",Data!$D$2:$D$60,$A11,Data!$F$2:$F$60,"uncommenced_leases")/1000) | F11: =IF(COUNTIFS(Data!$A$2:$A$60,"NVDA",Data!$D$2:$D$60,$A11,Data!$F$2:$F$60,"uncommenced_leases")=0,"",SUMIFS(Data!$H$2:$H$60,Data!$A$2:$A$60,"NVDA",Data!$D$2:$D$60,$A11,Data!$F$2:$F$60,"uncommenced_leases")/1000) | G11: =IF(COUNTIFS(Data!$A$2:$A$60,"ORCL",Data!$D$2:$D$60,$A11,Data!$F$2:$F$60,"uncommenced_leases")=0,"",SUMIFS(Data!$H$2:$H$60,Data!$A$2:$A$60,"ORCL",Data!$D$2:$D$60,$A11,Data!$F$2:$F$60,"uncommenced_leases")/1000) | H11: =IF(COUNT(B11:G11)=0,"",SUM(B11:G11)) | I11: =COUNT(B11:G11)&" of 6"
A12: 2025Q2 | B12: =IF(COUNTIFS(Data!$A$2:$A$60,"GOOGL",Data!$D$2:$D$60,$A12,Data!$F$2:$F$60,"uncommenced_leases")=0,"",SUMIFS(Data!$H$2:$H$60,Data!$A$2:$A$60,"GOOGL",Data!$D$2:$D$60,$A12,Data!$F$2:$F$60,"uncommenced_leases")/1000) | C12: =IF(COUNTIFS(Data!$A$2:$A$60,"MSFT",Data!$D$2:$D$60,$A12,Data!$F$2:$F$60,"uncommenced_leases")=0,"",SUMIFS(Data!$H$2:$H$60,Data!$A$2:$A$60,"MSFT",Data!$D$2:$D$60,$A12,Data!$F$2:$F$60,"uncommenced_leases")/1000) | D12: =IF(COUNTIFS(Data!$A$2:$A$60,"META",Data!$D$2:$D$60,$A12,Data!$F$2:$F$60,"uncommenced_leases")=0,"",SUMIFS(Data!$H$2:$H$60,Data!$A$2:$A$60,"META",Data!$D$2:$D$60,$A12,Data!$F$2:$F$60,"uncommenced_leases")/1000) | E12: =IF(COUNTIFS(Data!$A$2:$A$60,"AMZN",Data!$D$2:$D$60,$A12,Data!$F$2:$F$60,"uncommenced_leases")=0,"",SUMIFS(Data!$H$2:$H$60,Data!$A$2:$A$60,"AMZN",Data!$D$2:$D$60,$A12,Data!$F$2:$F$60,"uncommenced_leases")/1000) | F12: =IF(COUNTIFS(Data!$A$2:$A$60,"NVDA",Data!$D$2:$D$60,$A12,Data!$F$2:$F$60,"uncommenced_leases")=0,"",SUMIFS(Data!$H$2:$H$60,Data!$A$2:$A$60,"NVDA",Data!$D$2:$D$60,$A12,Data!$F$2:$F$60,"uncommenced_leases")/1000) | G12: =IF(COUNTIFS(Data!$A$2:$A$60,"ORCL",Data!$D$2:$D$60,$A12,Data!$F$2:$F$60,"uncommenced_leases")=0,"",SUMIFS(Data!$H$2:$H$60,Data!$A$2:$A$60,"ORCL",Data!$D$2:$D$60,$A12,Data!$F$2:$F$60,"uncommenced_leases")/1000) | H12: =IF(COUNT(B12:G12)=0,"",SUM(B12:G12)) | I12: =COUNT(B12:G12)&" of 6"
A13: 2025Q3 | B13: =IF(COUNTIFS(Data!$A$2:$A$60,"GOOGL",Data!$D$2:$D$60,$A13,Data!$F$2:$F$60,"uncommenced_leases")=0,"",SUMIFS(Data!$H$2:$H$60,Data!$A$2:$A$60,"GOOGL",Data!$D$2:$D$60,$A13,Data!$F$2:$F$60,"uncommenced_leases")/1000) | C13: =IF(COUNTIFS(Data!$A$2:$A$60,"MSFT",Data!$D$2:$D$60,$A13,Data!$F$2:$F$60,"uncommenced_leases")=0,"",SUMIFS(Data!$H$2:$H$60,Data!$A$2:$A$60,"MSFT",Data!$D$2:$D$60,$A13,Data!$F$2:$F$60,"uncommenced_leases")/1000) | D13: =IF(COUNTIFS(Data!$A$2:$A$60,"META",Data!$D$2:$D$60,$A13,Data!$F$2:$F$60,"uncommenced_leases")=0,"",SUMIFS(Data!$H$2:$H$60,Data!$A$2:$A$60,"META",Data!$D$2:$D$60,$A13,Data!$F$2:$F$60,"uncommenced_leases")/1000) | E13: =IF(COUNTIFS(Data!$A$2:$A$60,"AMZN",Data!$D$2:$D$60,$A13,Data!$F$2:$F$60,"uncommenced_leases")=0,"",SUMIFS(Data!$H$2:$H$60,Data!$A$2:$A$60,"AMZN",Data!$D$2:$D$60,$A13,Data!$F$2:$F$60,"uncommenced_leases")/1000) | F13: =IF(COUNTIFS(Data!$A$2:$A$60,"NVDA",Data!$D$2:$D$60,$A13,Data!$F$2:$F$60,"uncommenced_leases")=0,"",SUMIFS(Data!$H$2:$H$60,Data!$A$2:$A$60,"NVDA",Data!$D$2:$D$60,$A13,Data!$F$2:$F$60,"uncommenced_leases")/1000) | G13: =IF(COUNTIFS(Data!$A$2:$A$60,"ORCL",Data!$D$2:$D$60,$A13,Data!$F$2:$F$60,"uncommenced_leases")=0,"",SUMIFS(Data!$H$2:$H$60,Data!$A$2:$A$60,"ORCL",Data!$D$2:$D$60,$A13,Data!$F$2:$F$60,"uncommenced_leases")/1000) | H13: =IF(COUNT(B13:G13)=0,"",SUM(B13:G13)) | I13: =COUNT(B13:G13)&" of 6"
A14: 2025Q4 | B14: =IF(COUNTIFS(Data!$A$2:$A$60,"GOOGL",Data!$D$2:$D$60,$A14,Data!$F$2:$F$60,"uncommenced_leases")=0,"",SUMIFS(Data!$H$2:$H$60,Data!$A$2:$A$60,"GOOGL",Data!$D$2:$D$60,$A14,Data!$F$2:$F$60,"uncommenced_leases")/1000) | C14: =IF(COUNTIFS(Data!$A$2:$A$60,"MSFT",Data!$D$2:$D$60,$A14,Data!$F$2:$F$60,"uncommenced_leases")=0,"",SUMIFS(Data!$H$2:$H$60,Data!$A$2:$A$60,"MSFT",Data!$D$2:$D$60,$A14,Data!$F$2:$F$60,"uncommenced_leases")/1000) | D14: =IF(COUNTIFS(Data!$A$2:$A$60,"META",Data!$D$2:$D$60,$A14,Data!$F$2:$F$60,"uncommenced_leases")=0,"",SUMIFS(Data!$H$2:$H$60,Data!$A$2:$A$60,"META",Data!$D$2:$D$60,$A14,Data!$F$2:$F$60,"uncommenced_leases")/1000) | E14: =IF(COUNTIFS(Data!$A$2:$A$60,"AMZN",Data!$D$2:$D$60,$A14,Data!$F$2:$F$60,"uncommenced_leases")=0,"",SUMIFS(Data!$H$2:$H$60,Data!$A$2:$A$60,"AMZN",Data!$D$2:$D$60,$A14,Data!$F$2:$F$60,"uncommenced_leases")/1000) | F14: =IF(COUNTIFS(Data!$A$2:$A$60,"NVDA",Data!$D$2:$D$60,$A14,Data!$F$2:$F$60,"uncommenced_leases")=0,"",SUMIFS(Data!$H$2:$H$60,Data!$A$2:$A$60,"NVDA",Data!$D$2:$D$60,$A14,Data!$F$2:$F$60,"uncommenced_leases")/1000) | G14: =IF(COUNTIFS(Data!$A$2:$A$60,"ORCL",Data!$D$2:$D$60,$A14,Data!$F$2:$F$60,"uncommenced_leases")=0,"",SUMIFS(Data!$H$2:$H$60,Data!$A$2:$A$60,"ORCL",Data!$D$2:$D$60,$A14,Data!$F$2:$F$60,"uncommenced_leases")/1000) | H14: =IF(COUNT(B14:G14)=0,"",SUM(B14:G14)) | I14: =COUNT(B14:G14)&" of 6"
A15: 2026Q1 | B15: =IF(COUNTIFS(Data!$A$2:$A$60,"GOOGL",Data!$D$2:$D$60,$A15,Data!$F$2:$F$60,"uncommenced_leases")=0,"",SUMIFS(Data!$H$2:$H$60,Data!$A$2:$A$60,"GOOGL",Data!$D$2:$D$60,$A15,Data!$F$2:$F$60,"uncommenced_leases")/1000) | C15: =IF(COUNTIFS(Data!$A$2:$A$60,"MSFT",Data!$D$2:$D$60,$A15,Data!$F$2:$F$60,"uncommenced_leases")=0,"",SUMIFS(Data!$H$2:$H$60,Data!$A$2:$A$60,"MSFT",Data!$D$2:$D$60,$A15,Data!$F$2:$F$60,"uncommenced_leases")/1000) | D15: =IF(COUNTIFS(Data!$A$2:$A$60,"META",Data!$D$2:$D$60,$A15,Data!$F$2:$F$60,"uncommenced_leases")=0,"",SUMIFS(Data!$H$2:$H$60,Data!$A$2:$A$60,"META",Data!$D$2:$D$60,$A15,Data!$F$2:$F$60,"uncommenced_leases")/1000) | E15: =IF(COUNTIFS(Data!$A$2:$A$60,"AMZN",Data!$D$2:$D$60,$A15,Data!$F$2:$F$60,"uncommenced_leases")=0,"",SUMIFS(Data!$H$2:$H$60,Data!$A$2:$A$60,"AMZN",Data!$D$2:$D$60,$A15,Data!$F$2:$F$60,"uncommenced_leases")/1000) | F15: =IF(COUNTIFS(Data!$A$2:$A$60,"NVDA",Data!$D$2:$D$60,$A15,Data!$F$2:$F$60,"uncommenced_leases")=0,"",SUMIFS(Data!$H$2:$H$60,Data!$A$2:$A$60,"NVDA",Data!$D$2:$D$60,$A15,Data!$F$2:$F$60,"uncommenced_leases")/1000) | G15: =IF(COUNTIFS(Data!$A$2:$A$60,"ORCL",Data!$D$2:$D$60,$A15,Data!$F$2:$F$60,"uncommenced_leases")=0,"",SUMIFS(Data!$H$2:$H$60,Data!$A$2:$A$60,"ORCL",Data!$D$2:$D$60,$A15,Data!$F$2:$F$60,"uncommenced_leases")/1000) | H15: =IF(COUNT(B15:G15)=0,"",SUM(B15:G15)) | I15: =COUNT(B15:G15)&" of 6"
A16: 2026Q2 | B16: =IF(COUNTIFS(Data!$A$2:$A$60,"GOOGL",Data!$D$2:$D$60,$A16,Data!$F$2:$F$60,"uncommenced_leases")=0,"",SUMIFS(Data!$H$2:$H$60,Data!$A$2:$A$60,"GOOGL",Data!$D$2:$D$60,$A16,Data!$F$2:$F$60,"uncommenced_leases")/1000) | C16: =IF(COUNTIFS(Data!$A$2:$A$60,"MSFT",Data!$D$2:$D$60,$A16,Data!$F$2:$F$60,"uncommenced_leases")=0,"",SUMIFS(Data!$H$2:$H$60,Data!$A$2:$A$60,"MSFT",Data!$D$2:$D$60,$A16,Data!$F$2:$F$60,"uncommenced_leases")/1000) | D16: =IF(COUNTIFS(Data!$A$2:$A$60,"META",Data!$D$2:$D$60,$A16,Data!$F$2:$F$60,"uncommenced_leases")=0,"",SUMIFS(Data!$H$2:$H$60,Data!$A$2:$A$60,"META",Data!$D$2:$D$60,$A16,Data!$F$2:$F$60,"uncommenced_leases")/1000) | E16: =IF(COUNTIFS(Data!$A$2:$A$60,"AMZN",Data!$D$2:$D$60,$A16,Data!$F$2:$F$60,"uncommenced_leases")=0,"",SUMIFS(Data!$H$2:$H$60,Data!$A$2:$A$60,"AMZN",Data!$D$2:$D$60,$A16,Data!$F$2:$F$60,"uncommenced_leases")/1000) | F16: =IF(COUNTIFS(Data!$A$2:$A$60,"NVDA",Data!$D$2:$D$60,$A16,Data!$F$2:$F$60,"uncommenced_leases")=0,"",SUMIFS(Data!$H$2:$H$60,Data!$A$2:$A$60,"NVDA",Data!$D$2:$D$60,$A16,Data!$F$2:$F$60,"uncommenced_leases")/1000) | G16: =IF(COUNTIFS(Data!$A$2:$A$60,"ORCL",Data!$D$2:$D$60,$A16,Data!$F$2:$F$60,"uncommenced_leases")=0,"",SUMIFS(Data!$H$2:$H$60,Data!$A$2:$A$60,"ORCL",Data!$D$2:$D$60,$A16,Data!$F$2:$F$60,"uncommenced_leases")/1000) | H16: =IF(COUNT(B16:G16)=0,"",SUM(B16:G16)) | I16: =COUNT(B16:G16)&" of 6"
A18: Change over the period | B18: =IF(OR(B16="",COUNT(B5:B16)<2),"",B16-INDEX(B5:B16,MATCH(TRUE,INDEX(B5:B16<>"",0),0))) | C18: =IF(OR(C16="",COUNT(C5:C16)<2),"",C16-INDEX(C5:C16,MATCH(TRUE,INDEX(C5:C16<>"",0),0))) | D18: =IF(OR(D16="",COUNT(D5:D16)<2),"",D16-INDEX(D5:D16,MATCH(TRUE,INDEX(D5:D16<>"",0),0))) | E18: =IF(OR(E16="",COUNT(E5:E16)<2),"",E16-INDEX(E5:E16,MATCH(TRUE,INDEX(E5:E16<>"",0),0))) | F18: =IF(OR(F16="",COUNT(F5:F16)<2),"",F16-INDEX(F5:F16,MATCH(TRUE,INDEX(F5:F16<>"",0),0))) | G18: =IF(OR(G16="",COUNT(G5:G16)<2),"",G16-INDEX(G5:G16,MATCH(TRUE,INDEX(G5:G16<>"",0),0)))
A19: Latest less the first quarter that company disclosed, so it is not comparable across columns with different start dates.

Sheet Purchase commitments
A1: Purchase commitments
A2: USD billions. Blank = not disclosed / not sourced; never treated as zero.
A4: Calendar quarter | B4: GOOGL | C4: MSFT | D4: META | E4: AMZN | F4: NVDA | G4: ORCL | H4: Total | I4: Reported
A5: 2023Q3 | B5: =IF(COUNTIFS(Data!$A$2:$A$60,"GOOGL",Data!$D$2:$D$60,$A5,Data!$F$2:$F$60,"purchase_commitments")=0,"",SUMIFS(Data!$H$2:$H$60,Data!$A$2:$A$60,"GOOGL",Data!$D$2:$D$60,$A5,Data!$F$2:$F$60,"purchase_commitments")/1000) | C5: =IF(COUNTIFS(Data!$A$2:$A$60,"MSFT",Data!$D$2:$D$60,$A5,Data!$F$2:$F$60,"purchase_commitments")=0,"",SUMIFS(Data!$H$2:$H$60,Data!$A$2:$A$60,"MSFT",Data!$D$2:$D$60,$A5,Data!$F$2:$F$60,"purchase_commitments")/1000) | D5: =IF(COUNTIFS(Data!$A$2:$A$60,"META",Data!$D$2:$D$60,$A5,Data!$F$2:$F$60,"purchase_commitments")=0,"",SUMIFS(Data!$H$2:$H$60,Data!$A$2:$A$60,"META",Data!$D$2:$D$60,$A5,Data!$F$2:$F$60,"purchase_commitments")/1000) | E5: =IF(COUNTIFS(Data!$A$2:$A$60,"AMZN",Data!$D$2:$D$60,$A5,Data!$F$2:$F$60,"purchase_commitments")=0,"",SUMIFS(Data!$H$2:$H$60,Data!$A$2:$A$60,"AMZN",Data!$D$2:$D$60,$A5,Data!$F$2:$F$60,"purchase_commitments")/1000) | F5: =IF(COUNTIFS(Data!$A$2:$A$60,"NVDA",Data!$D$2:$D$60,$A5,Data!$F$2:$F$60,"purchase_commitments")=0,"",SUMIFS(Data!$H$2:$H$60,Data!$A$2:$A$60,"NVDA",Data!$D$2:$D$60,$A5,Data!$F$2:$F$60,"purchase_commitments")/1000) | G5: =IF(COUNTIFS(Data!$A$2:$A$60,"ORCL",Data!$D$2:$D$60,$A5,Data!$F$2:$F$60,"purchase_commitments")=0,"",SUMIFS(Data!$H$2:$H$60,Data!$A$2:$A$60,"ORCL",Data!$D$2:$D$60,$A5,Data!$F$2:$F$60,"purchase_commitments")/1000) | H5: =IF(COUNT(B5:G5)=0,"",SUM(B5:G5)) | I5: =COUNT(B5:G5)&" of 6"
A6: 2023Q4 | B6: =IF(COUNTIFS(Data!$A$2:$A$60,"GOOGL",Data!$D$2:$D$60,$A6,Data!$F$2:$F$60,"purchase_commitments")=0,"",SUMIFS(Data!$H$2:$H$60,Data!$A$2:$A$60,"GOOGL",Data!$D$2:$D$60,$A6,Data!$F$2:$F$60,"purchase_commitments")/1000) | C6: =IF(COUNTIFS(Data!$A$2:$A$60,"MSFT",Data!$D$2:$D$60,$A6,Data!$F$2:$F$60,"purchase_commitments")=0,"",SUMIFS(Data!$H$2:$H$60,Data!$A$2:$A$60,"MSFT",Data!$D$2:$D$60,$A6,Data!$F$2:$F$60,"purchase_commitments")/1000) | D6: =IF(COUNTIFS(Data!$A$2:$A$60,"META",Data!$D$2:$D$60,$A6,Data!$F$2:$F$60,"purchase_commitments")=0,"",SUMIFS(Data!$H$2:$H$60,Data!$A$2:$A$60,"META",Data!$D$2:$D$60,$A6,Data!$F$2:$F$60,"purchase_commitments")/1000) | E6: =IF(COUNTIFS(Data!$A$2:$A$60,"AMZN",Data!$D$2:$D$60,$A6,Data!$F$2:$F$60,"purchase_commitments")=0,"",SUMIFS(Data!$H$2:$H$60,Data!$A$2:$A$60,"AMZN",Data!$D$2:$D$60,$A6,Data!$F$2:$F$60,"purchase_commitments")/1000) | F6: =IF(COUNTIFS(Data!$A$2:$A$60,"NVDA",Data!$D$2:$D$60,$A6,Data!$F$2:$F$60,"purchase_commitments")=0,"",SUMIFS(Data!$H$2:$H$60,Data!$A$2:$A$60,"NVDA",Data!$D$2:$D$60,$A6,Data!$F$2:$F$60,"purchase_commitments")/1000) | G6: =IF(COUNTIFS(Data!$A$2:$A$60,"ORCL",Data!$D$2:$D$60,$A6,Data!$F$2:$F$60,"purchase_commitments")=0,"",SUMIFS(Data!$H$2:$H$60,Data!$A$2:$A$60,"ORCL",Data!$D$2:$D$60,$A6,Data!$F$2:$F$60,"purchase_commitments")/1000) | H6: =IF(COUNT(B6:G6)=0,"",SUM(B6:G6)) | I6: =COUNT(B6:G6)&" of 6"
A7: 2024Q1 | B7: =IF(COUNTIFS(Data!$A$2:$A$60,"GOOGL",Data!$D$2:$D$60,$A7,Data!$F$2:$F$60,"purchase_commitments")=0,"",SUMIFS(Data!$H$2:$H$60,Data!$A$2:$A$60,"GOOGL",Data!$D$2:$D$60,$A7,Data!$F$2:$F$60,"purchase_commitments")/1000) | C7: =IF(COUNTIFS(Data!$A$2:$A$60,"MSFT",Data!$D$2:$D$60,$A7,Data!$F$2:$F$60,"purchase_commitments")=0,"",SUMIFS(Data!$H$2:$H$60,Data!$A$2:$A$60,"MSFT",Data!$D$2:$D$60,$A7,Data!$F$2:$F$60,"purchase_commitments")/1000) | D7: =IF(COUNTIFS(Data!$A$2:$A$60,"META",Data!$D$2:$D$60,$A7,Data!$F$2:$F$60,"purchase_commitments")=0,"",SUMIFS(Data!$H$2:$H$60,Data!$A$2:$A$60,"META",Data!$D$2:$D$60,$A7,Data!$F$2:$F$60,"purchase_commitments")/1000) | E7: =IF(COUNTIFS(Data!$A$2:$A$60,"AMZN",Data!$D$2:$D$60,$A7,Data!$F$2:$F$60,"purchase_commitments")=0,"",SUMIFS(Data!$H$2:$H$60,Data!$A$2:$A$60,"AMZN",Data!$D$2:$D$60,$A7,Data!$F$2:$F$60,"purchase_commitments")/1000) | F7: =IF(COUNTIFS(Data!$A$2:$A$60,"NVDA",Data!$D$2:$D$60,$A7,Data!$F$2:$F$60,"purchase_commitments")=0,"",SUMIFS(Data!$H$2:$H$60,Data!$A$2:$A$60,"NVDA",Data!$D$2:$D$60,$A7,Data!$F$2:$F$60,"purchase_commitments")/1000) | G7: =IF(COUNTIFS(Data!$A$2:$A$60,"ORCL",Data!$D$2:$D$60,$A7,Data!$F$2:$F$60,"purchase_commitments")=0,"",SUMIFS(Data!$H$2:$H$60,Data!$A$2:$A$60,"ORCL",Data!$D$2:$D$60,$A7,Data!$F$2:$F$60,"purchase_commitments")/1000) | H7: =IF(COUNT(B7:G7)=0,"",SUM(B7:G7)) | I7: =COUNT(B7:G7)&" of 6"
A8: 2024Q2 | B8: =IF(COUNTIFS(Data!$A$2:$A$60,"GOOGL",Data!$D$2:$D$60,$A8,Data!$F$2:$F$60,"purchase_commitments")=0,"",SUMIFS(Data!$H$2:$H$60,Data!$A$2:$A$60,"GOOGL",Data!$D$2:$D$60,$A8,Data!$F$2:$F$60,"purchase_commitments")/1000) | C8: =IF(COUNTIFS(Data!$A$2:$A$60,"MSFT",Data!$D$2:$D$60,$A8,Data!$F$2:$F$60,"purchase_commitments")=0,"",SUMIFS(Data!$H$2:$H$60,Data!$A$2:$A$60,"MSFT",Data!$D$2:$D$60,$A8,Data!$F$2:$F$60,"purchase_commitments")/1000) | D8: =IF(COUNTIFS(Data!$A$2:$A$60,"META",Data!$D$2:$D$60,$A8,Data!$F$2:$F$60,"purchase_commitments")=0,"",SUMIFS(Data!$H$2:$H$60,Data!$A$2:$A$60,"META",Data!$D$2:$D$60,$A8,Data!$F$2:$F$60,"purchase_commitments")/1000) | E8: =IF(COUNTIFS(Data!$A$2:$A$60,"AMZN",Data!$D$2:$D$60,$A8,Data!$F$2:$F$60,"purchase_commitments")=0,"",SUMIFS(Data!$H$2:$H$60,Data!$A$2:$A$60,"AMZN",Data!$D$2:$D$60,$A8,Data!$F$2:$F$60,"purchase_commitments")/1000) | F8: =IF(COUNTIFS(Data!$A$2:$A$60,"NVDA",Data!$D$2:$D$60,$A8,Data!$F$2:$F$60,"purchase_commitments")=0,"",SUMIFS(Data!$H$2:$H$60,Data!$A$2:$A$60,"NVDA",Data!$D$2:$D$60,$A8,Data!$F$2:$F$60,"purchase_commitments")/1000) | G8: =IF(COUNTIFS(Data!$A$2:$A$60,"ORCL",Data!$D$2:$D$60,$A8,Data!$F$2:$F$60,"purchase_commitments")=0,"",SUMIFS(Data!$H$2:$H$60,Data!$A$2:$A$60,"ORCL",Data!$D$2:$D$60,$A8,Data!$F$2:$F$60,"purchase_commitments")/1000) | H8: =IF(COUNT(B8:G8)=0,"",SUM(B8:G8)) | I8: =COUNT(B8:G8)&" of 6"
A9: 2024Q3 | B9: =IF(COUNTIFS(Data!$A$2:$A$60,"GOOGL",Data!$D$2:$D$60,$A9,Data!$F$2:$F$60,"purchase_commitments")=0,"",SUMIFS(Data!$H$2:$H$60,Data!$A$2:$A$60,"GOOGL",Data!$D$2:$D$60,$A9,Data!$F$2:$F$60,"purchase_commitments")/1000) | C9: =IF(COUNTIFS(Data!$A$2:$A$60,"MSFT",Data!$D$2:$D$60,$A9,Data!$F$2:$F$60,"purchase_commitments")=0,"",SUMIFS(Data!$H$2:$H$60,Data!$A$2:$A$60,"MSFT",Data!$D$2:$D$60,$A9,Data!$F$2:$F$60,"purchase_commitments")/1000) | D9: =IF(COUNTIFS(Data!$A$2:$A$60,"META",Data!$D$2:$D$60,$A9,Data!$F$2:$F$60,"purchase_commitments")=0,"",SUMIFS(Data!$H$2:$H$60,Data!$A$2:$A$60,"META",Data!$D$2:$D$60,$A9,Data!$F$2:$F$60,"purchase_commitments")/1000) | E9: =IF(COUNTIFS(Data!$A$2:$A$60,"AMZN",Data!$D$2:$D$60,$A9,Data!$F$2:$F$60,"purchase_commitments")=0,"",SUMIFS(Data!$H$2:$H$60,Data!$A$2:$A$60,"AMZN",Data!$D$2:$D$60,$A9,Data!$F$2:$F$60,"purchase_commitments")/1000) | F9: =IF(COUNTIFS(Data!$A$2:$A$60,"NVDA",Data!$D$2:$D$60,$A9,Data!$F$2:$F$60,"purchase_commitments")=0,"",SUMIFS(Data!$H$2:$H$60,Data!$A$2:$A$60,"NVDA",Data!$D$2:$D$60,$A9,Data!$F$2:$F$60,"purchase_commitments")/1000) | G9: =IF(COUNTIFS(Data!$A$2:$A$60,"ORCL",Data!$D$2:$D$60,$A9,Data!$F$2:$F$60,"purchase_commitments")=0,"",SUMIFS(Data!$H$2:$H$60,Data!$A$2:$A$60,"ORCL",Data!$D$2:$D$60,$A9,Data!$F$2:$F$60,"purchase_commitments")/1000) | H9: =IF(COUNT(B9:G9)=0,"",SUM(B9:G9)) | I9: =COUNT(B9:G9)&" of 6"
A10: 2024Q4 | B10: =IF(COUNTIFS(Data!$A$2:$A$60,"GOOGL",Data!$D$2:$D$60,$A10,Data!$F$2:$F$60,"purchase_commitments")=0,"",SUMIFS(Data!$H$2:$H$60,Data!$A$2:$A$60,"GOOGL",Data!$D$2:$D$60,$A10,Data!$F$2:$F$60,"purchase_commitments")/1000) | C10: =IF(COUNTIFS(Data!$A$2:$A$60,"MSFT",Data!$D$2:$D$60,$A10,Data!$F$2:$F$60,"purchase_commitments")=0,"",SUMIFS(Data!$H$2:$H$60,Data!$A$2:$A$60,"MSFT",Data!$D$2:$D$60,$A10,Data!$F$2:$F$60,"purchase_commitments")/1000) | D10: =IF(COUNTIFS(Data!$A$2:$A$60,"META",Data!$D$2:$D$60,$A10,Data!$F$2:$F$60,"purchase_commitments")=0,"",SUMIFS(Data!$H$2:$H$60,Data!$A$2:$A$60,"META",Data!$D$2:$D$60,$A10,Data!$F$2:$F$60,"purchase_commitments")/1000) | E10: =IF(COUNTIFS(Data!$A$2:$A$60,"AMZN",Data!$D$2:$D$60,$A10,Data!$F$2:$F$60,"purchase_commitments")=0,"",SUMIFS(Data!$H$2:$H$60,Data!$A$2:$A$60,"AMZN",Data!$D$2:$D$60,$A10,Data!$F$2:$F$60,"purchase_commitments")/1000) | F10: =IF(COUNTIFS(Data!$A$2:$A$60,"NVDA",Data!$D$2:$D$60,$A10,Data!$F$2:$F$60,"purchase_commitments")=0,"",SUMIFS(Data!$H$2:$H$60,Data!$A$2:$A$60,"NVDA",Data!$D$2:$D$60,$A10,Data!$F$2:$F$60,"purchase_commitments")/1000) | G10: =IF(COUNTIFS(Data!$A$2:$A$60,"ORCL",Data!$D$2:$D$60,$A10,Data!$F$2:$F$60,"purchase_commitments")=0,"",SUMIFS(Data!$H$2:$H$60,Data!$A$2:$A$60,"ORCL",Data!$D$2:$D$60,$A10,Data!$F$2:$F$60,"purchase_commitments")/1000) | H10: =IF(COUNT(B10:G10)=0,"",SUM(B10:G10)) | I10: =COUNT(B10:G10)&" of 6"
A11: 2025Q1 | B11: =IF(COUNTIFS(Data!$A$2:$A$60,"GOOGL",Data!$D$2:$D$60,$A11,Data!$F$2:$F$60,"purchase_commitments")=0,"",SUMIFS(Data!$H$2:$H$60,Data!$A$2:$A$60,"GOOGL",Data!$D$2:$D$60,$A11,Data!$F$2:$F$60,"purchase_commitments")/1000) | C11: =IF(COUNTIFS(Data!$A$2:$A$60,"MSFT",Data!$D$2:$D$60,$A11,Data!$F$2:$F$60,"purchase_commitments")=0,"",SUMIFS(Data!$H$2:$H$60,Data!$A$2:$A$60,"MSFT",Data!$D$2:$D$60,$A11,Data!$F$2:$F$60,"purchase_commitments")/1000) | D11: =IF(COUNTIFS(Data!$A$2:$A$60,"META",Data!$D$2:$D$60,$A11,Data!$F$2:$F$60,"purchase_commitments")=0,"",SUMIFS(Data!$H$2:$H$60,Data!$A$2:$A$60,"META",Data!$D$2:$D$60,$A11,Data!$F$2:$F$60,"purchase_commitments")/1000) | E11: =IF(COUNTIFS(Data!$A$2:$A$60,"AMZN",Data!$D$2:$D$60,$A11,Data!$F$2:$F$60,"purchase_commitments")=0,"",SUMIFS(Data!$H$2:$H$60,Data!$A$2:$A$60,"AMZN",Data!$D$2:$D$60,$A11,Data!$F$2:$F$60,"purchase_commitments")/1000) | F11: =IF(COUNTIFS(Data!$A$2:$A$60,"NVDA",Data!$D$2:$D$60,$A11,Data!$F$2:$F$60,"purchase_commitments")=0,"",SUMIFS(Data!$H$2:$H$60,Data!$A$2:$A$60,"NVDA",Data!$D$2:$D$60,$A11,Data!$F$2:$F$60,"purchase_commitments")/1000) | G11: =IF(COUNTIFS(Data!$A$2:$A$60,"ORCL",Data!$D$2:$D$60,$A11,Data!$F$2:$F$60,"purchase_commitments")=0,"",SUMIFS(Data!$H$2:$H$60,Data!$A$2:$A$60,"ORCL",Data!$D$2:$D$60,$A11,Data!$F$2:$F$60,"purchase_commitments")/1000) | H11: =IF(COUNT(B11:G11)=0,"",SUM(B11:G11)) | I11: =COUNT(B11:G11)&" of 6"
A12: 2025Q2 | B12: =IF(COUNTIFS(Data!$A$2:$A$60,"GOOGL",Data!$D$2:$D$60,$A12,Data!$F$2:$F$60,"purchase_commitments")=0,"",SUMIFS(Data!$H$2:$H$60,Data!$A$2:$A$60,"GOOGL",Data!$D$2:$D$60,$A12,Data!$F$2:$F$60,"purchase_commitments")/1000) | C12: =IF(COUNTIFS(Data!$A$2:$A$60,"MSFT",Data!$D$2:$D$60,$A12,Data!$F$2:$F$60,"purchase_commitments")=0,"",SUMIFS(Data!$H$2:$H$60,Data!$A$2:$A$60,"MSFT",Data!$D$2:$D$60,$A12,Data!$F$2:$F$60,"purchase_commitments")/1000) | D12: =IF(COUNTIFS(Data!$A$2:$A$60,"META",Data!$D$2:$D$60,$A12,Data!$F$2:$F$60,"purchase_commitments")=0,"",SUMIFS(Data!$H$2:$H$60,Data!$A$2:$A$60,"META",Data!$D$2:$D$60,$A12,Data!$F$2:$F$60,"purchase_commitments")/1000) | E12: =IF(COUNTIFS(Data!$A$2:$A$60,"AMZN",Data!$D$2:$D$60,$A12,Data!$F$2:$F$60,"purchase_commitments")=0,"",SUMIFS(Data!$H$2:$H$60,Data!$A$2:$A$60,"AMZN",Data!$D$2:$D$60,$A12,Data!$F$2:$F$60,"purchase_commitments")/1000) | F12: =IF(COUNTIFS(Data!$A$2:$A$60,"NVDA",Data!$D$2:$D$60,$A12,Data!$F$2:$F$60,"purchase_commitments")=0,"",SUMIFS(Data!$H$2:$H$60,Data!$A$2:$A$60,"NVDA",Data!$D$2:$D$60,$A12,Data!$F$2:$F$60,"purchase_commitments")/1000) | G12: =IF(COUNTIFS(Data!$A$2:$A$60,"ORCL",Data!$D$2:$D$60,$A12,Data!$F$2:$F$60,"purchase_commitments")=0,"",SUMIFS(Data!$H$2:$H$60,Data!$A$2:$A$60,"ORCL",Data!$D$2:$D$60,$A12,Data!$F$2:$F$60,"purchase_commitments")/1000) | H12: =IF(COUNT(B12:G12)=0,"",SUM(B12:G12)) | I12: =COUNT(B12:G12)&" of 6"
A13: 2025Q3 | B13: =IF(COUNTIFS(Data!$A$2:$A$60,"GOOGL",Data!$D$2:$D$60,$A13,Data!$F$2:$F$60,"purchase_commitments")=0,"",SUMIFS(Data!$H$2:$H$60,Data!$A$2:$A$60,"GOOGL",Data!$D$2:$D$60,$A13,Data!$F$2:$F$60,"purchase_commitments")/1000) | C13: =IF(COUNTIFS(Data!$A$2:$A$60,"MSFT",Data!$D$2:$D$60,$A13,Data!$F$2:$F$60,"purchase_commitments")=0,"",SUMIFS(Data!$H$2:$H$60,Data!$A$2:$A$60,"MSFT",Data!$D$2:$D$60,$A13,Data!$F$2:$F$60,"purchase_commitments")/1000) | D13: =IF(COUNTIFS(Data!$A$2:$A$60,"META",Data!$D$2:$D$60,$A13,Data!$F$2:$F$60,"purchase_commitments")=0,"",SUMIFS(Data!$H$2:$H$60,Data!$A$2:$A$60,"META",Data!$D$2:$D$60,$A13,Data!$F$2:$F$60,"purchase_commitments")/1000) | E13: =IF(COUNTIFS(Data!$A$2:$A$60,"AMZN",Data!$D$2:$D$60,$A13,Data!$F$2:$F$60,"purchase_commitments")=0,"",SUMIFS(Data!$H$2:$H$60,Data!$A$2:$A$60,"AMZN",Data!$D$2:$D$60,$A13,Data!$F$2:$F$60,"purchase_commitments")/1000) | F13: =IF(COUNTIFS(Data!$A$2:$A$60,"NVDA",Data!$D$2:$D$60,$A13,Data!$F$2:$F$60,"purchase_commitments")=0,"",SUMIFS(Data!$H$2:$H$60,Data!$A$2:$A$60,"NVDA",Data!$D$2:$D$60,$A13,Data!$F$2:$F$60,"purchase_commitments")/1000) | G13: =IF(COUNTIFS(Data!$A$2:$A$60,"ORCL",Data!$D$2:$D$60,$A13,Data!$F$2:$F$60,"purchase_commitments")=0,"",SUMIFS(Data!$H$2:$H$60,Data!$A$2:$A$60,"ORCL",Data!$D$2:$D$60,$A13,Data!$F$2:$F$60,"purchase_commitments")/1000) | H13: =IF(COUNT(B13:G13)=0,"",SUM(B13:G13)) | I13: =COUNT(B13:G13)&" of 6"
A14: 2025Q4 | B14: =IF(COUNTIFS(Data!$A$2:$A$60,"GOOGL",Data!$D$2:$D$60,$A14,Data!$F$2:$F$60,"purchase_commitments")=0,"",SUMIFS(Data!$H$2:$H$60,Data!$A$2:$A$60,"GOOGL",Data!$D$2:$D$60,$A14,Data!$F$2:$F$60,"purchase_commitments")/1000) | C14: =IF(COUNTIFS(Data!$A$2:$A$60,"MSFT",Data!$D$2:$D$60,$A14,Data!$F$2:$F$60,"purchase_commitments")=0,"",SUMIFS(Data!$H$2:$H$60,Data!$A$2:$A$60,"MSFT",Data!$D$2:$D$60,$A14,Data!$F$2:$F$60,"purchase_commitments")/1000) | D14: =IF(COUNTIFS(Data!$A$2:$A$60,"META",Data!$D$2:$D$60,$A14,Data!$F$2:$F$60,"purchase_commitments")=0,"",SUMIFS(Data!$H$2:$H$60,Data!$A$2:$A$60,"META",Data!$D$2:$D$60,$A14,Data!$F$2:$F$60,"purchase_commitments")/1000) | E14: =IF(COUNTIFS(Data!$A$2:$A$60,"AMZN",Data!$D$2:$D$60,$A14,Data!$F$2:$F$60,"purchase_commitments")=0,"",SUMIFS(Data!$H$2:$H$60,Data!$A$2:$A$60,"AMZN",Data!$D$2:$D$60,$A14,Data!$F$2:$F$60,"purchase_commitments")/1000) | F14: =IF(COUNTIFS(Data!$A$2:$A$60,"NVDA",Data!$D$2:$D$60,$A14,Data!$F$2:$F$60,"purchase_commitments")=0,"",SUMIFS(Data!$H$2:$H$60,Data!$A$2:$A$60,"NVDA",Data!$D$2:$D$60,$A14,Data!$F$2:$F$60,"purchase_commitments")/1000) | G14: =IF(COUNTIFS(Data!$A$2:$A$60,"ORCL",Data!$D$2:$D$60,$A14,Data!$F$2:$F$60,"purchase_commitments")=0,"",SUMIFS(Data!$H$2:$H$60,Data!$A$2:$A$60,"ORCL",Data!$D$2:$D$60,$A14,Data!$F$2:$F$60,"purchase_commitments")/1000) | H14: =IF(COUNT(B14:G14)=0,"",SUM(B14:G14)) | I14: =COUNT(B14:G14)&" of 6"
A15: 2026Q1 | B15: =IF(COUNTIFS(Data!$A$2:$A$60,"GOOGL",Data!$D$2:$D$60,$A15,Data!$F$2:$F$60,"purchase_commitments")=0,"",SUMIFS(Data!$H$2:$H$60,Data!$A$2:$A$60,"GOOGL",Data!$D$2:$D$60,$A15,Data!$F$2:$F$60,"purchase_commitments")/1000) | C15: =IF(COUNTIFS(Data!$A$2:$A$60,"MSFT",Data!$D$2:$D$60,$A15,Data!$F$2:$F$60,"purchase_commitments")=0,"",SUMIFS(Data!$H$2:$H$60,Data!$A$2:$A$60,"MSFT",Data!$D$2:$D$60,$A15,Data!$F$2:$F$60,"purchase_commitments")/1000) | D15: =IF(COUNTIFS(Data!$A$2:$A$60,"META",Data!$D$2:$D$60,$A15,Data!$F$2:$F$60,"purchase_commitments")=0,"",SUMIFS(Data!$H$2:$H$60,Data!$A$2:$A$60,"META",Data!$D$2:$D$60,$A15,Data!$F$2:$F$60,"purchase_commitments")/1000) | E15: =IF(COUNTIFS(Data!$A$2:$A$60,"AMZN",Data!$D$2:$D$60,$A15,Data!$F$2:$F$60,"purchase_commitments")=0,"",SUMIFS(Data!$H$2:$H$60,Data!$A$2:$A$60,"AMZN",Data!$D$2:$D$60,$A15,Data!$F$2:$F$60,"purchase_commitments")/1000) | F15: =IF(COUNTIFS(Data!$A$2:$A$60,"NVDA",Data!$D$2:$D$60,$A15,Data!$F$2:$F$60,"purchase_commitments")=0,"",SUMIFS(Data!$H$2:$H$60,Data!$A$2:$A$60,"NVDA",Data!$D$2:$D$60,$A15,Data!$F$2:$F$60,"purchase_commitments")/1000) | G15: =IF(COUNTIFS(Data!$A$2:$A$60,"ORCL",Data!$D$2:$D$60,$A15,Data!$F$2:$F$60,"purchase_commitments")=0,"",SUMIFS(Data!$H$2:$H$60,Data!$A$2:$A$60,"ORCL",Data!$D$2:$D$60,$A15,Data!$F$2:$F$60,"purchase_commitments")/1000) | H15: =IF(COUNT(B15:G15)=0,"",SUM(B15:G15)) | I15: =COUNT(B15:G15)&" of 6"
A16: 2026Q2 | B16: =IF(COUNTIFS(Data!$A$2:$A$60,"GOOGL",Data!$D$2:$D$60,$A16,Data!$F$2:$F$60,"purchase_commitments")=0,"",SUMIFS(Data!$H$2:$H$60,Data!$A$2:$A$60,"GOOGL",Data!$D$2:$D$60,$A16,Data!$F$2:$F$60,"purchase_commitments")/1000) | C16: =IF(COUNTIFS(Data!$A$2:$A$60,"MSFT",Data!$D$2:$D$60,$A16,Data!$F$2:$F$60,"purchase_commitments")=0,"",SUMIFS(Data!$H$2:$H$60,Data!$A$2:$A$60,"MSFT",Data!$D$2:$D$60,$A16,Data!$F$2:$F$60,"purchase_commitments")/1000) | D16: =IF(COUNTIFS(Data!$A$2:$A$60,"META",Data!$D$2:$D$60,$A16,Data!$F$2:$F$60,"purchase_commitments")=0,"",SUMIFS(Data!$H$2:$H$60,Data!$A$2:$A$60,"META",Data!$D$2:$D$60,$A16,Data!$F$2:$F$60,"purchase_commitments")/1000) | E16: =IF(COUNTIFS(Data!$A$2:$A$60,"AMZN",Data!$D$2:$D$60,$A16,Data!$F$2:$F$60,"purchase_commitments")=0,"",SUMIFS(Data!$H$2:$H$60,Data!$A$2:$A$60,"AMZN",Data!$D$2:$D$60,$A16,Data!$F$2:$F$60,"purchase_commitments")/1000) | F16: =IF(COUNTIFS(Data!$A$2:$A$60,"NVDA",Data!$D$2:$D$60,$A16,Data!$F$2:$F$60,"purchase_commitments")=0,"",SUMIFS(Data!$H$2:$H$60,Data!$A$2:$A$60,"NVDA",Data!$D$2:$D$60,$A16,Data!$F$2:$F$60,"purchase_commitments")/1000) | G16: =IF(COUNTIFS(Data!$A$2:$A$60,"ORCL",Data!$D$2:$D$60,$A16,Data!$F$2:$F$60,"purchase_commitments")=0,"",SUMIFS(Data!$H$2:$H$60,Data!$A$2:$A$60,"ORCL",Data!$D$2:$D$60,$A16,Data!$F$2:$F$60,"purchase_commitments")/1000) | H16: =IF(COUNT(B16:G16)=0,"",SUM(B16:G16)) | I16: =COUNT(B16:G16)&" of 6"
A18: Change over the period | B18: =IF(OR(B16="",COUNT(B5:B16)<2),"",B16-INDEX(B5:B16,MATCH(TRUE,INDEX(B5:B16<>"",0),0))) | C18: =IF(OR(C16="",COUNT(C5:C16)<2),"",C16-INDEX(C5:C16,MATCH(TRUE,INDEX(C5:C16<>"",0),0))) | D18: =IF(OR(D16="",COUNT(D5:D16)<2),"",D16-INDEX(D5:D16,MATCH(TRUE,INDEX(D5:D16<>"",0),0))) | E18: =IF(OR(E16="",COUNT(E5:E16)<2),"",E16-INDEX(E5:E16,MATCH(TRUE,INDEX(E5:E16<>"",0),0))) | F18: =IF(OR(F16="",COUNT(F5:F16)<2),"",F16-INDEX(F5:F16,MATCH(TRUE,INDEX(F5:F16<>"",0),0))) | G18: =IF(OR(G16="",COUNT(G5:G16)<2),"",G16-INDEX(G5:G16,MATCH(TRUE,INDEX(G5:G16<>"",0),0)))
A19: Latest less the first quarter that company disclosed, so it is not comparable across columns with different start dates.

Sheet Combined
A1: Uncommenced leases + purchase commitments
A2: USD billions. A company is summed only where both legs exist, so a blank here means at least one leg is missing for that quarter.
A4: Calendar quarter | B4: GOOGL | C4: MSFT | D4: META | E4: AMZN | F4: NVDA | G4: ORCL | H4: Total
A5: 2023Q3 | B5: =IF(AND('Uncommenced lease commitments'!B5<>"",'Purchase commitments'!B5<>""),'Uncommenced lease commitments'!B5+'Purchase commitments'!B5,"") | C5: =IF(AND('Uncommenced lease commitments'!C5<>"",'Purchase commitments'!C5<>""),'Uncommenced lease commitments'!C5+'Purchase commitments'!C5,"") | D5: =IF(AND('Uncommenced lease commitments'!D5<>"",'Purchase commitments'!D5<>""),'Uncommenced lease commitments'!D5+'Purchase commitments'!D5,"") | E5: =IF(AND('Uncommenced lease commitments'!E5<>"",'Purchase commitments'!E5<>""),'Uncommenced lease commitments'!E5+'Purchase commitments'!E5,"") | F5: =IF(AND('Uncommenced lease commitments'!F5<>"",'Purchase commitments'!F5<>""),'Uncommenced lease commitments'!F5+'Purchase commitments'!F5,"") | G5: =IF(AND('Uncommenced lease commitments'!G5<>"",'Purchase commitments'!G5<>""),'Uncommenced lease commitments'!G5+'Purchase commitments'!G5,"") | H5: =IF(COUNT(B5:G5)=0,"",SUM(B5:G5))
A6: 2023Q4 | B6: =IF(AND('Uncommenced lease commitments'!B6<>"",'Purchase commitments'!B6<>""),'Uncommenced lease commitments'!B6+'Purchase commitments'!B6,"") | C6: =IF(AND('Uncommenced lease commitments'!C6<>"",'Purchase commitments'!C6<>""),'Uncommenced lease commitments'!C6+'Purchase commitments'!C6,"") | D6: =IF(AND('Uncommenced lease commitments'!D6<>"",'Purchase commitments'!D6<>""),'Uncommenced lease commitments'!D6+'Purchase commitments'!D6,"") | E6: =IF(AND('Uncommenced lease commitments'!E6<>"",'Purchase commitments'!E6<>""),'Uncommenced lease commitments'!E6+'Purchase commitments'!E6,"") | F6: =IF(AND('Uncommenced lease commitments'!F6<>"",'Purchase commitments'!F6<>""),'Uncommenced lease commitments'!F6+'Purchase commitments'!F6,"") | G6: =IF(AND('Uncommenced lease commitments'!G6<>"",'Purchase commitments'!G6<>""),'Uncommenced lease commitments'!G6+'Purchase commitments'!G6,"") | H6: =IF(COUNT(B6:G6)=0,"",SUM(B6:G6))
A7: 2024Q1 | B7: =IF(AND('Uncommenced lease commitments'!B7<>"",'Purchase commitments'!B7<>""),'Uncommenced lease commitments'!B7+'Purchase commitments'!B7,"") | C7: =IF(AND('Uncommenced lease commitments'!C7<>"",'Purchase commitments'!C7<>""),'Uncommenced lease commitments'!C7+'Purchase commitments'!C7,"") | D7: =IF(AND('Uncommenced lease commitments'!D7<>"",'Purchase commitments'!D7<>""),'Uncommenced lease commitments'!D7+'Purchase commitments'!D7,"") | E7: =IF(AND('Uncommenced lease commitments'!E7<>"",'Purchase commitments'!E7<>""),'Uncommenced lease commitments'!E7+'Purchase commitments'!E7,"") | F7: =IF(AND('Uncommenced lease commitments'!F7<>"",'Purchase commitments'!F7<>""),'Uncommenced lease commitments'!F7+'Purchase commitments'!F7,"") | G7: =IF(AND('Uncommenced lease commitments'!G7<>"",'Purchase commitments'!G7<>""),'Uncommenced lease commitments'!G7+'Purchase commitments'!G7,"") | H7: =IF(COUNT(B7:G7)=0,"",SUM(B7:G7))
A8: 2024Q2 | B8: =IF(AND('Uncommenced lease commitments'!B8<>"",'Purchase commitments'!B8<>""),'Uncommenced lease commitments'!B8+'Purchase commitments'!B8,"") | C8: =IF(AND('Uncommenced lease commitments'!C8<>"",'Purchase commitments'!C8<>""),'Uncommenced lease commitments'!C8+'Purchase commitments'!C8,"") | D8: =IF(AND('Uncommenced lease commitments'!D8<>"",'Purchase commitments'!D8<>""),'Uncommenced lease commitments'!D8+'Purchase commitments'!D8,"") | E8: =IF(AND('Uncommenced lease commitments'!E8<>"",'Purchase commitments'!E8<>""),'Uncommenced lease commitments'!E8+'Purchase commitments'!E8,"") | F8: =IF(AND('Uncommenced lease commitments'!F8<>"",'Purchase commitments'!F8<>""),'Uncommenced lease commitments'!F8+'Purchase commitments'!F8,"") | G8: =IF(AND('Uncommenced lease commitments'!G8<>"",'Purchase commitments'!G8<>""),'Uncommenced lease commitments'!G8+'Purchase commitments'!G8,"") | H8: =IF(COUNT(B8:G8)=0,"",SUM(B8:G8))
A9: 2024Q3 | B9: =IF(AND('Uncommenced lease commitments'!B9<>"",'Purchase commitments'!B9<>""),'Uncommenced lease commitments'!B9+'Purchase commitments'!B9,"") | C9: =IF(AND('Uncommenced lease commitments'!C9<>"",'Purchase commitments'!C9<>""),'Uncommenced lease commitments'!C9+'Purchase commitments'!C9,"") | D9: =IF(AND('Uncommenced lease commitments'!D9<>"",'Purchase commitments'!D9<>""),'Uncommenced lease commitments'!D9+'Purchase commitments'!D9,"") | E9: =IF(AND('Uncommenced lease commitments'!E9<>"",'Purchase commitments'!E9<>""),'Uncommenced lease commitments'!E9+'Purchase commitments'!E9,"") | F9: =IF(AND('Uncommenced lease commitments'!F9<>"",'Purchase commitments'!F9<>""),'Uncommenced lease commitments'!F9+'Purchase commitments'!F9,"") | G9: =IF(AND('Uncommenced lease commitments'!G9<>"",'Purchase commitments'!G9<>""),'Uncommenced lease commitments'!G9+'Purchase commitments'!G9,"") | H9: =IF(COUNT(B9:G9)=0,"",SUM(B9:G9))
A10: 2024Q4 | B10: =IF(AND('Uncommenced lease commitments'!B10<>"",'Purchase commitments'!B10<>""),'Uncommenced lease commitments'!B10+'Purchase commitments'!B10,"") | C10: =IF(AND('Uncommenced lease commitments'!C10<>"",'Purchase commitments'!C10<>""),'Uncommenced lease commitments'!C10+'Purchase commitments'!C10,"") | D10: =IF(AND('Uncommenced lease commitments'!D10<>"",'Purchase commitments'!D10<>""),'Uncommenced lease commitments'!D10+'Purchase commitments'!D10,"") | E10: =IF(AND('Uncommenced lease commitments'!E10<>"",'Purchase commitments'!E10<>""),'Uncommenced lease commitments'!E10+'Purchase commitments'!E10,"") | F10: =IF(AND('Uncommenced lease commitments'!F10<>"",'Purchase commitments'!F10<>""),'Uncommenced lease commitments'!F10+'Purchase commitments'!F10,"") | G10: =IF(AND('Uncommenced lease commitments'!G10<>"",'Purchase commitments'!G10<>""),'Uncommenced lease commitments'!G10+'Purchase commitments'!G10,"") | H10: =IF(COUNT(B10:G10)=0,"",SUM(B10:G10))
A11: 2025Q1 | B11: =IF(AND('Uncommenced lease commitments'!B11<>"",'Purchase commitments'!B11<>""),'Uncommenced lease commitments'!B11+'Purchase commitments'!B11,"") | C11: =IF(AND('Uncommenced lease commitments'!C11<>"",'Purchase commitments'!C11<>""),'Uncommenced lease commitments'!C11+'Purchase commitments'!C11,"") | D11: =IF(AND('Uncommenced lease commitments'!D11<>"",'Purchase commitments'!D11<>""),'Uncommenced lease commitments'!D11+'Purchase commitments'!D11,"") | E11: =IF(AND('Uncommenced lease commitments'!E11<>"",'Purchase commitments'!E11<>""),'Uncommenced lease commitments'!E11+'Purchase commitments'!E11,"") | F11: =IF(AND('Uncommenced lease commitments'!F11<>"",'Purchase commitments'!F11<>""),'Uncommenced lease commitments'!F11+'Purchase commitments'!F11,"") | G11: =IF(AND('Uncommenced lease commitments'!G11<>"",'Purchase commitments'!G11<>""),'Uncommenced lease commitments'!G11+'Purchase commitments'!G11,"") | H11: =IF(COUNT(B11:G11)=0,"",SUM(B11:G11))
A12: 2025Q2 | B12: =IF(AND('Uncommenced lease commitments'!B12<>"",'Purchase commitments'!B12<>""),'Uncommenced lease commitments'!B12+'Purchase commitments'!B12,"") | C12: =IF(AND('Uncommenced lease commitments'!C12<>"",'Purchase commitments'!C12<>""),'Uncommenced lease commitments'!C12+'Purchase commitments'!C12,"") | D12: =IF(AND('Uncommenced lease commitments'!D12<>"",'Purchase commitments'!D12<>""),'Uncommenced lease commitments'!D12+'Purchase commitments'!D12,"") | E12: =IF(AND('Uncommenced lease commitments'!E12<>"",'Purchase commitments'!E12<>""),'Uncommenced lease commitments'!E12+'Purchase commitments'!E12,"") | F12: =IF(AND('Uncommenced lease commitments'!F12<>"",'Purchase commitments'!F12<>""),'Uncommenced lease commitments'!F12+'Purchase commitments'!F12,"") | G12: =IF(AND('Uncommenced lease commitments'!G12<>"",'Purchase commitments'!G12<>""),'Uncommenced lease commitments'!G12+'Purchase commitments'!G12,"") | H12: =IF(COUNT(B12:G12)=0,"",SUM(B12:G12))
A13: 2025Q3 | B13: =IF(AND('Uncommenced lease commitments'!B13<>"",'Purchase commitments'!B13<>""),'Uncommenced lease commitments'!B13+'Purchase commitments'!B13,"") | C13: =IF(AND('Uncommenced lease commitments'!C13<>"",'Purchase commitments'!C13<>""),'Uncommenced lease commitments'!C13+'Purchase commitments'!C13,"") | D13: =IF(AND('Uncommenced lease commitments'!D13<>"",'Purchase commitments'!D13<>""),'Uncommenced lease commitments'!D13+'Purchase commitments'!D13,"") | E13: =IF(AND('Uncommenced lease commitments'!E13<>"",'Purchase commitments'!E13<>""),'Uncommenced lease commitments'!E13+'Purchase commitments'!E13,"") | F13: =IF(AND('Uncommenced lease commitments'!F13<>"",'Purchase commitments'!F13<>""),'Uncommenced lease commitments'!F13+'Purchase commitments'!F13,"") | G13: =IF(AND('Uncommenced lease commitments'!G13<>"",'Purchase commitments'!G13<>""),'Uncommenced lease commitments'!G13+'Purchase commitments'!G13,"") | H13: =IF(COUNT(B13:G13)=0,"",SUM(B13:G13))
A14: 2025Q4 | B14: =IF(AND('Uncommenced lease commitments'!B14<>"",'Purchase commitments'!B14<>""),'Uncommenced lease commitments'!B14+'Purchase commitments'!B14,"") | C14: =IF(AND('Uncommenced lease commitments'!C14<>"",'Purchase commitments'!C14<>""),'Uncommenced lease commitments'!C14+'Purchase commitments'!C14,"") | D14: =IF(AND('Uncommenced lease commitments'!D14<>"",'Purchase commitments'!D14<>""),'Uncommenced lease commitments'!D14+'Purchase commitments'!D14,"") | E14: =IF(AND('Uncommenced lease commitments'!E14<>"",'Purchase commitments'!E14<>""),'Uncommenced lease commitments'!E14+'Purchase commitments'!E14,"") | F14: =IF(AND('Uncommenced lease commitments'!F14<>"",'Purchase commitments'!F14<>""),'Uncommenced lease commitments'!F14+'Purchase commitments'!F14,"") | G14: =IF(AND('Uncommenced lease commitments'!G14<>"",'Purchase commitments'!G14<>""),'Uncommenced lease commitments'!G14+'Purchase commitments'!G14,"") | H14: =IF(COUNT(B14:G14)=0,"",SUM(B14:G14))
A15: 2026Q1 | B15: =IF(AND('Uncommenced lease commitments'!B15<>"",'Purchase commitments'!B15<>""),'Uncommenced lease commitments'!B15+'Purchase commitments'!B15,"") | C15: =IF(AND('Uncommenced lease commitments'!C15<>"",'Purchase commitments'!C15<>""),'Uncommenced lease commitments'!C15+'Purchase commitments'!C15,"") | D15: =IF(AND('Uncommenced lease commitments'!D15<>"",'Purchase commitments'!D15<>""),'Uncommenced lease commitments'!D15+'Purchase commitments'!D15,"") | E15: =IF(AND('Uncommenced lease commitments'!E15<>"",'Purchase commitments'!E15<>""),'Uncommenced lease commitments'!E15+'Purchase commitments'!E15,"") | F15: =IF(AND('Uncommenced lease commitments'!F15<>"",'Purchase commitments'!F15<>""),'Uncommenced lease commitments'!F15+'Purchase commitments'!F15,"") | G15: =IF(AND('Uncommenced lease commitments'!G15<>"",'Purchase commitments'!G15<>""),'Uncommenced lease commitments'!G15+'Purchase commitments'!G15,"") | H15: =IF(COUNT(B15:G15)=0,"",SUM(B15:G15))
A16: 2026Q2 | B16: =IF(AND('Uncommenced lease commitments'!B16<>"",'Purchase commitments'!B16<>""),'Uncommenced lease commitments'!B16+'Purchase commitments'!B16,"") | C16: =IF(AND('Uncommenced lease commitments'!C16<>"",'Purchase commitments'!C16<>""),'Uncommenced lease commitments'!C16+'Purchase commitments'!C16,"") | D16: =IF(AND('Uncommenced lease commitments'!D16<>"",'Purchase commitments'!D16<>""),'Uncommenced lease commitments'!D16+'Purchase commitments'!D16,"") | E16: =IF(AND('Uncommenced lease commitments'!E16<>"",'Purchase commitments'!E16<>""),'Uncommenced lease commitments'!E16+'Purchase commitments'!E16,"") | F16: =IF(AND('Uncommenced lease commitments'!F16<>"",'Purchase commitments'!F16<>""),'Uncommenced lease commitments'!F16+'Purchase commitments'!F16,"") | G16: =IF(AND('Uncommenced lease commitments'!G16<>"",'Purchase commitments'!G16<>""),'Uncommenced lease commitments'!G16+'Purchase commitments'!G16,"") | H16: =IF(COUNT(B16:G16)=0,"",SUM(B16:G16))

Sheet Coverage
A1: What is populated, and how well sourced
A2: Read this before using the numbers. It is the honest map of where the dataset is solid and where it is thin.
A4: Ticker | B4: Metric | C4: Quarters populated | D4: of 12 | E4: filing / filing_table | F4: press / derived
